2023-08-30 19:10:21,269 - telegram.ext.Application - INFO - Application started
2023-08-30 19:10:42,825 - __main__ - INFO - Entered withdraw_all_eth_command
2023-08-30 19:21:11,396 - telegram.ext.Application - INFO - Application started
2023-08-30 19:21:17,344 - __main__ - INFO - Entered withdraw_all_eth_command
2023-08-30 19:21:17,345 - __main__ - INFO - User ID extracted: 6117012777
2023-08-30 19:21:17,346 - __main__ - INFO - About to check ETH balance
2023-08-30 19:21:17,428 - __main__ - INFO - ETH balance checked: 0.05
2023-08-30 19:21:17,428 - __main__ - INFO - ETH balance converted to float: 0.05
2023-08-30 19:21:17,429 - __main__ - INFO - ETH balance is positive, asking for destination address
2023-08-30 19:23:33,230 - telegram.ext.Application - INFO - Application started
2023-08-30 19:23:43,238 - __main__ - INFO - Entered withdraw_all_eth_command
2023-08-30 19:23:43,239 - __main__ - INFO - User ID extracted: 6117012777
2023-08-30 19:23:43,239 - __main__ - INFO - About to check ETH balance
2023-08-30 19:23:43,386 - __main__ - INFO - ETH balance checked: 0.05
2023-08-30 19:23:43,386 - __main__ - INFO - ETH balance converted to float: 0.05
2023-08-30 19:23:43,387 - __main__ - INFO - ETH balance is positive, asking for destination address
2023-08-30 19:28:16,626 - telegram.ext.Application - INFO - Application started
2023-08-30 19:33:10,783 - telegram.ext.Application - INFO - Application started
2023-08-30 19:33:16,742 - __main__ - INFO - Entered withdraw_all_eth_command
2023-08-30 19:33:16,742 - __main__ - INFO - User ID extracted: 6117012777
2023-08-30 19:33:16,742 - __main__ - INFO - About to check ETH balance
2023-08-30 19:33:16,830 - __main__ - INFO - ETH balance checked: 0.05
2023-08-30 19:33:16,830 - __main__ - INFO - ETH balance converted to float: 0.05
2023-08-30 19:33:16,830 - __main__ - INFO - ETH balance is positive, asking for destination address
2023-08-30 19:41:18,642 - telegram.ext.Application - INFO - Application started
2023-08-30 19:41:39,800 - __main__ - INFO - Entered withdraw_all_eth_command
2023-08-30 19:41:39,802 - __main__ - INFO - User ID extracted: 6117012777
2023-08-30 19:41:39,802 - __main__ - INFO - About to check ETH balance
2023-08-30 19:41:39,920 - __main__ - INFO - ETH balance checked: 0.05
2023-08-30 19:41:39,921 - __main__ - INFO - ETH balance converted to float: 0.05
2023-08-30 19:41:39,921 - __main__ - INFO - ETH balance is positive, asking for destination address
2023-08-30 19:44:22,124 - telegram.ext.Application - INFO - Application started
2023-08-30 19:44:37,344 - __main__ - INFO - Entered withdraw_all_eth_command
2023-08-30 19:44:37,346 - __main__ - INFO - User ID extracted: 6117012777
2023-08-30 19:44:37,433 - __main__ - INFO - About to check ETH balance
2023-08-30 19:44:37,433 - __main__ - INFO - ETH balance checked: 0.05
2023-08-30 19:44:37,434 - __main__ - INFO - ETH balance converted to float: 0.05
2023-08-30 19:44:37,681 - __main__ - INFO - ETH balance is positive, asking for destination address
2023-08-30 20:09:52,035 - telegram.ext.Application - INFO - Application started
2023-08-30 20:19:21,883 - telegram.ext.Application - INFO - Application started
2023-08-30 20:19:52,533 - telegram.ext.Application - ERROR - No error handlers are registered, logging exception.
Traceback (most recent call last):
  File "/home/runner/Telegram-Bot-Generate-Wallet/.pythonlibs/lib/python3.10/site-packages/telegram/ext/_application.py", line 1173, in process_update
    await coroutine
  File "/home/runner/Telegram-Bot-Generate-Wallet/.pythonlibs/lib/python3.10/site-packages/telegram/ext/_conversationhandler.py", line 825, in handle_update
    new_state: object = await handler.handle_update(
  File "/home/runner/Telegram-Bot-Generate-Wallet/.pythonlibs/lib/python3.10/site-packages/telegram/ext/_basehandler.py", line 141, in handle_update
    return await self.callback(update, context)
  File "main.py", line 68, in input_eth_address
    if re.match("^0x[a-fA-F0-9]{40}$", to_address):
NameError: name 're' is not defined
2023-08-30 20:20:47,921 - telegram.ext.Application - INFO - Application started
2023-08-30 20:20:58,293 - __main__ - INFO - Transaction successful for user_id: 6117012777, to_address: 0xD5042ba7e365CeA492Ee9a2715c5cf47a012663a
2023-08-30 20:26:43,881 - telegram.ext.Application - INFO - Application started
2023-08-30 20:27:25,746 - __main__ - INFO - Transaction successful for user_id: 6117012777, to_address: 0xD5042ba7e365CeA492Ee9a2715c5cf47a012663a
2023-08-30 20:29:41,537 - telegram.ext.Application - INFO - Application started
2023-08-30 20:38:52,056 - telegram.ext.Updater - ERROR - Error while getting Updates: httpx.RemoteProtocolError: Server disconnected without sending a response.
2023-08-30 20:38:52,056 - telegram.ext.Application - ERROR - No error handlers are registered, logging exception.
Traceback (most recent call last):
  File "/home/runner/Telegram-Bot-Generate-Wallet/.pythonlibs/lib/python3.10/site-packages/httpx/_transports/default.py", line 60, in map_httpcore_exceptions
    yield
  File "/home/runner/Telegram-Bot-Generate-Wallet/.pythonlibs/lib/python3.10/site-packages/httpx/_transports/default.py", line 353, in handle_async_request
    resp = await self._pool.handle_async_request(req)
  File "/home/runner/Telegram-Bot-Generate-Wallet/.pythonlibs/lib/python3.10/site-packages/httpcore/_async/connection_pool.py", line 262, in handle_async_request
    raise exc
  File "/home/runner/Telegram-Bot-Generate-Wallet/.pythonlibs/lib/python3.10/site-packages/httpcore/_async/connection_pool.py", line 245, in handle_async_request
    response = await connection.handle_async_request(request)
  File "/home/runner/Telegram-Bot-Generate-Wallet/.pythonlibs/lib/python3.10/site-packages/httpcore/_async/connection.py", line 96, in handle_async_request
    return await self._connection.handle_async_request(request)
  File "/home/runner/Telegram-Bot-Generate-Wallet/.pythonlibs/lib/python3.10/site-packages/httpcore/_async/http11.py", line 121, in handle_async_request
    raise exc
  File "/home/runner/Telegram-Bot-Generate-Wallet/.pythonlibs/lib/python3.10/site-packages/httpcore/_async/http11.py", line 99, in handle_async_request
    ) = await self._receive_response_headers(**kwargs)
  File "/home/runner/Telegram-Bot-Generate-Wallet/.pythonlibs/lib/python3.10/site-packages/httpcore/_async/http11.py", line 164, in _receive_response_headers
    event = await self._receive_event(timeout=timeout)
  File "/home/runner/Telegram-Bot-Generate-Wallet/.pythonlibs/lib/python3.10/site-packages/httpcore/_async/http11.py", line 214, in _receive_event
    raise RemoteProtocolError(msg)
httpcore.RemoteProtocolError: Server disconnected without sending a response.

The above exception was the direct cause of the following exception:

Traceback (most recent call last):
  File "/home/runner/Telegram-Bot-Generate-Wallet/.pythonlibs/lib/python3.10/site-packages/telegram/request/_httpxrequest.py", line 216, in do_request
    res = await self._client.request(
  File "/home/runner/Telegram-Bot-Generate-Wallet/.pythonlibs/lib/python3.10/site-packages/httpx/_client.py", line 1530, in request
    return await self.send(request, auth=auth, follow_redirects=follow_redirects)
  File "/home/runner/Telegram-Bot-Generate-Wallet/.pythonlibs/lib/python3.10/site-packages/httpx/_client.py", line 1617, in send
    response = await self._send_handling_auth(
  File "/home/runner/Telegram-Bot-Generate-Wallet/.pythonlibs/lib/python3.10/site-packages/httpx/_client.py", line 1645, in _send_handling_auth
    response = await self._send_handling_redirects(
  File "/home/runner/Telegram-Bot-Generate-Wallet/.pythonlibs/lib/python3.10/site-packages/httpx/_client.py", line 1682, in _send_handling_redirects
    response = await self._send_single_request(request)
  File "/home/runner/Telegram-Bot-Generate-Wallet/.pythonlibs/lib/python3.10/site-packages/httpx/_client.py", line 1719, in _send_single_request
    response = await transport.handle_async_request(request)
  File "/home/runner/Telegram-Bot-Generate-Wallet/.pythonlibs/lib/python3.10/site-packages/httpx/_transports/default.py", line 352, in handle_async_request
    with map_httpcore_exceptions():
  File "/nix/store/xf54733x4chbawkh1qvy9i1i4mlscy1c-python3-3.10.11/lib/python3.10/contextlib.py", line 153, in __exit__
    self.gen.throw(typ, value, traceback)
  File "/home/runner/Telegram-Bot-Generate-Wallet/.pythonlibs/lib/python3.10/site-packages/httpx/_transports/default.py", line 77, in map_httpcore_exceptions
    raise mapped_exc(message) from exc
httpx.RemoteProtocolError: Server disconnected without sending a response.

The above exception was the direct cause of the following exception:

Traceback (most recent call last):
  File "/home/runner/Telegram-Bot-Generate-Wallet/.pythonlibs/lib/python3.10/site-packages/telegram/ext/_updater.py", line 604, in _network_loop_retry
    if not await action_cb():
  File "/home/runner/Telegram-Bot-Generate-Wallet/.pythonlibs/lib/python3.10/site-packages/telegram/ext/_updater.py", line 331, in polling_action_cb
    raise exc
  File "/home/runner/Telegram-Bot-Generate-Wallet/.pythonlibs/lib/python3.10/site-packages/telegram/ext/_updater.py", line 320, in polling_action_cb
    updates = await self.bot.get_updates(
  File "/home/runner/Telegram-Bot-Generate-Wallet/.pythonlibs/lib/python3.10/site-packages/telegram/ext/_extbot.py", line 550, in get_updates
    updates = await super().get_updates(
  File "/home/runner/Telegram-Bot-Generate-Wallet/.pythonlibs/lib/python3.10/site-packages/telegram/_bot.py", line 388, in decorator
    result = await func(self, *args, **kwargs)  # skipcq: PYL-E1102
  File "/home/runner/Telegram-Bot-Generate-Wallet/.pythonlibs/lib/python3.10/site-packages/telegram/_bot.py", line 3668, in get_updates
    await self._post(
  File "/home/runner/Telegram-Bot-Generate-Wallet/.pythonlibs/lib/python3.10/site-packages/telegram/_bot.py", line 476, in _post
    return await self._do_post(
  File "/home/runner/Telegram-Bot-Generate-Wallet/.pythonlibs/lib/python3.10/site-packages/telegram/ext/_extbot.py", line 332, in _do_post
    return await super()._do_post(
  File "/home/runner/Telegram-Bot-Generate-Wallet/.pythonlibs/lib/python3.10/site-packages/telegram/_bot.py", line 504, in _do_post
    return await request.post(
  File "/home/runner/Telegram-Bot-Generate-Wallet/.pythonlibs/lib/python3.10/site-packages/telegram/request/_baserequest.py", line 168, in post
    result = await self._request_wrapper(
  File "/home/runner/Telegram-Bot-Generate-Wallet/.pythonlibs/lib/python3.10/site-packages/telegram/request/_baserequest.py", line 288, in _request_wrapper
    raise exc
  File "/home/runner/Telegram-Bot-Generate-Wallet/.pythonlibs/lib/python3.10/site-packages/telegram/request/_baserequest.py", line 278, in _request_wrapper
    code, payload = await self.do_request(
  File "/home/runner/Telegram-Bot-Generate-Wallet/.pythonlibs/lib/python3.10/site-packages/telegram/request/_httpxrequest.py", line 240, in do_request
    raise NetworkError(f"httpx.{err.__class__.__name__}: {err}") from err
telegram.error.NetworkError: httpx.RemoteProtocolError: Server disconnected without sending a response.
2023-08-31 04:37:00,807 - telegram.ext.Application - INFO - Application started
2023-08-31 04:53:53,670 - telegram.ext.Application - INFO - Application started
2023-08-31 04:54:30,402 - telegram.ext.Application - INFO - Application started
2023-08-31 05:01:29,213 - telegram.ext.Application - INFO - Application started
2023-08-31 05:01:54,028 - telegram.ext.Application - INFO - Application started
2023-08-31 05:04:11,308 - telegram.ext.Application - INFO - Application started
2023-08-31 05:20:29,755 - telegram.ext.Application - INFO - Application started
2023-08-31 05:25:18,315 - telegram.ext.Application - INFO - Application started
2023-08-31 05:41:05,937 - telegram.ext.Application - INFO - Application started
2023-08-31 05:43:51,304 - telegram.ext.Application - INFO - Application started
2023-08-31 05:48:52,606 - telegram.ext.Application - INFO - Application started
2023-08-31 05:50:11,207 - telegram.ext.Application - INFO - Application started
2023-08-31 05:57:37,215 - telegram.ext.Application - INFO - Application started
2023-08-31 06:00:37,903 - telegram.ext.Application - INFO - Application started
2023-08-31 06:31:11,532 - telegram.ext.Application - INFO - Application started
2023-08-31 06:34:55,031 - telegram.ext.Application - INFO - Application started
2023-08-31 06:36:33,769 - telegram.ext.Application - INFO - Application started
2023-08-31 06:38:40,008 - telegram.ext.Application - INFO - Application started
2023-08-31 06:43:32,872 - telegram.ext.Application - INFO - Application started
2023-08-31 06:45:26,204 - telegram.ext.Application - INFO - Application started
2023-08-31 06:52:13,450 - telegram.ext.Application - INFO - Application started
2023-08-31 07:03:06,857 - telegram.ext.Application - INFO - Application started
2023-08-31 07:07:26,922 - telegram.ext.Application - INFO - Application started
2023-08-31 07:08:36,713 - telegram.ext.Application - INFO - Application started
2023-08-31 07:08:56,816 - telegram.ext.Application - INFO - Application started
2023-08-31 07:09:17,032 - telegram.ext.Application - ERROR - No error handlers are registered, logging exception.
Traceback (most recent call last):
  File "/home/runner/Telegram-Bot-Generate-Wallet/.pythonlibs/lib/python3.10/site-packages/telegram/ext/_application.py", line 1173, in process_update
    await coroutine
  File "/home/runner/Telegram-Bot-Generate-Wallet/.pythonlibs/lib/python3.10/site-packages/telegram/ext/_conversationhandler.py", line 825, in handle_update
    new_state: object = await handler.handle_update(
  File "/home/runner/Telegram-Bot-Generate-Wallet/.pythonlibs/lib/python3.10/site-packages/telegram/ext/_basehandler.py", line 141, in handle_update
    return await self.callback(update, context)
  File "main.py", line 224, in get_private_key
    return PRIVATE_KEY_ROUTES
NameError: name 'PRIVATE_KEY_ROUTES' is not defined
2023-08-31 07:09:23,068 - telegram.ext.Application - ERROR - No error handlers are registered, logging exception.
Traceback (most recent call last):
  File "/home/runner/Telegram-Bot-Generate-Wallet/.pythonlibs/lib/python3.10/site-packages/telegram/ext/_application.py", line 1173, in process_update
    await coroutine
  File "/home/runner/Telegram-Bot-Generate-Wallet/.pythonlibs/lib/python3.10/site-packages/telegram/ext/_conversationhandler.py", line 825, in handle_update
    new_state: object = await handler.handle_update(
  File "/home/runner/Telegram-Bot-Generate-Wallet/.pythonlibs/lib/python3.10/site-packages/telegram/ext/_basehandler.py", line 141, in handle_update
    return await self.callback(update, context)
  File "main.py", line 224, in get_private_key
    return PRIVATE_KEY_ROUTES
NameError: name 'PRIVATE_KEY_ROUTES' is not defined
2023-08-31 07:10:40,911 - telegram.ext.Application - INFO - Application started
2023-08-31 07:21:30,127 - telegram.ext.Application - INFO - Application started
2023-08-31 07:23:11,883 - telegram.ext.Application - INFO - Application started
2023-08-31 07:41:51,739 - telegram.ext.Application - INFO - Application started
2023-08-31 08:01:53,406 - telegram.ext.Application - INFO - Application started
2023-08-31 08:03:55,805 - telegram.ext.Application - INFO - Application started
2023-08-31 08:04:04,553 - root - INFO - Entered delete_wallet function
2023-08-31 08:04:04,553 - root - INFO - Attempting to delete file: private_keys/6117012777_private_key.txt
2023-08-31 08:04:04,554 - root - INFO - Successfully deleted private key for user 6117012777
2023-08-31 08:07:12,948 - telegram.ext.Application - INFO - Application started
2023-08-31 08:10:38,501 - telegram.ext.Application - INFO - Application started
2023-08-31 08:10:59,818 - root - INFO - Entered delete_wallet function
2023-08-31 08:10:59,828 - root - INFO - Attempting to delete file: private_keys/6117012777_private_key.txt
2023-08-31 08:10:59,835 - root - INFO - Successfully deleted private key for user 6117012777
2023-08-31 08:16:08,012 - telegram.ext.Application - INFO - Application started
2023-08-31 08:16:36,213 - root - INFO - Entered delete_wallet function
2023-08-31 08:16:36,503 - root - INFO - Attempting to delete file: private_keys/6117012777_private_key.txt
2023-08-31 08:16:36,508 - root - INFO - Successfully deleted private key for user 6117012777
2023-08-31 08:19:04,968 - telegram.ext.Application - INFO - Application started
2023-08-31 08:19:15,703 - root - INFO - Entered delete_wallet function
2023-08-31 08:19:16,013 - root - INFO - Attempting to delete file: private_keys/6117012777_private_key.txt
2023-08-31 08:19:16,026 - root - INFO - Successfully deleted private key for user 6117012777
2023-08-31 08:20:09,897 - telegram.ext.Application - INFO - Application started
2023-08-31 08:20:17,644 - root - INFO - Entered delete_wallet function
2023-08-31 08:20:17,949 - root - INFO - Attempting to delete file: private_keys/6117012777_private_key.txt
2023-08-31 08:20:18,018 - root - INFO - Successfully deleted private key for user 6117012777
2023-08-31 08:23:10,883 - telegram.ext.Application - INFO - Application started
2023-08-31 08:23:19,109 - root - INFO - Entered delete_wallet function
2023-08-31 08:23:19,314 - root - INFO - Attempting to delete file: private_keys/6117012777_private_key.txt
2023-08-31 08:23:19,315 - root - INFO - Successfully deleted private key for user 6117012777
2023-08-31 08:24:54,740 - telegram.ext.Application - INFO - Application started
2023-08-31 08:25:08,806 - root - INFO - Entered delete_wallet function
2023-08-31 08:25:09,017 - root - INFO - Attempting to delete file: private_keys/6117012777_private_key.txt
2023-08-31 08:25:09,018 - root - INFO - Successfully deleted private key for user 6117012777
2023-08-31 08:31:54,626 - telegram.ext.Application - INFO - Application started
2023-08-31 08:32:04,201 - telegram.ext.Application - ERROR - No error handlers are registered, logging exception.
Traceback (most recent call last):
  File "/home/runner/Telegram-Bot-Generate-Wallet/.pythonlibs/lib/python3.10/site-packages/telegram/ext/_application.py", line 1173, in process_update
    await coroutine
  File "/home/runner/Telegram-Bot-Generate-Wallet/.pythonlibs/lib/python3.10/site-packages/telegram/ext/_conversationhandler.py", line 825, in handle_update
    new_state: object = await handler.handle_update(
  File "/home/runner/Telegram-Bot-Generate-Wallet/.pythonlibs/lib/python3.10/site-packages/telegram/ext/_basehandler.py", line 141, in handle_update
    return await self.callback(update, context)
  File "main.py", line 112, in generate_wallet_command
    with open(f"private_keys/{user_id}_private_key.txt", "w") as f:
FileNotFoundError: [Errno 2] No such file or directory: 'private_keys/6117012777_private_key.txt'
2023-08-31 08:32:09,653 - telegram.ext.Application - ERROR - No error handlers are registered, logging exception.
Traceback (most recent call last):
  File "/home/runner/Telegram-Bot-Generate-Wallet/.pythonlibs/lib/python3.10/site-packages/telegram/ext/_application.py", line 1173, in process_update
    await coroutine
  File "/home/runner/Telegram-Bot-Generate-Wallet/.pythonlibs/lib/python3.10/site-packages/telegram/ext/_conversationhandler.py", line 825, in handle_update
    new_state: object = await handler.handle_update(
  File "/home/runner/Telegram-Bot-Generate-Wallet/.pythonlibs/lib/python3.10/site-packages/telegram/ext/_basehandler.py", line 141, in handle_update
    return await self.callback(update, context)
  File "main.py", line 112, in generate_wallet_command
    with open(f"private_keys/{user_id}_private_key.txt", "w") as f:
FileNotFoundError: [Errno 2] No such file or directory: 'private_keys/6117012777_private_key.txt'
2023-08-31 08:35:36,495 - telegram.ext.Application - INFO - Application started
2023-08-31 08:36:42,224 - telegram.ext.Application - INFO - Application started
2023-08-31 08:37:00,622 - root - INFO - Entered delete_wallet function
2023-08-31 08:37:00,902 - root - INFO - Attempting to delete file: private_keys/6117012777_private_key.txt
2023-08-31 08:37:00,905 - root - INFO - Successfully deleted private key for user 6117012777
2023-08-31 08:40:26,942 - telegram.ext.Application - INFO - Application started
2023-08-31 08:40:36,817 - telegram.ext.Application - ERROR - No error handlers are registered, logging exception.
Traceback (most recent call last):
  File "/home/runner/Telegram-Bot-Generate-Wallet/.pythonlibs/lib/python3.10/site-packages/telegram/ext/_application.py", line 1173, in process_update
    await coroutine
  File "/home/runner/Telegram-Bot-Generate-Wallet/.pythonlibs/lib/python3.10/site-packages/telegram/ext/_conversationhandler.py", line 825, in handle_update
    new_state: object = await handler.handle_update(
  File "/home/runner/Telegram-Bot-Generate-Wallet/.pythonlibs/lib/python3.10/site-packages/telegram/ext/_basehandler.py", line 141, in handle_update
    return await self.callback(update, context)
  File "main.py", line 87, in show_wallet_menu
    text=message_text,
NameError: name 'message_text' is not defined
2023-08-31 08:40:41,227 - telegram.ext.Application - ERROR - No error handlers are registered, logging exception.
Traceback (most recent call last):
  File "/home/runner/Telegram-Bot-Generate-Wallet/.pythonlibs/lib/python3.10/site-packages/telegram/ext/_application.py", line 1173, in process_update
    await coroutine
  File "/home/runner/Telegram-Bot-Generate-Wallet/.pythonlibs/lib/python3.10/site-packages/telegram/ext/_conversationhandler.py", line 825, in handle_update
    new_state: object = await handler.handle_update(
  File "/home/runner/Telegram-Bot-Generate-Wallet/.pythonlibs/lib/python3.10/site-packages/telegram/ext/_basehandler.py", line 141, in handle_update
    return await self.callback(update, context)
  File "main.py", line 87, in show_wallet_menu
    text=message_text,
NameError: name 'message_text' is not defined
2023-08-31 08:41:36,120 - telegram.ext.Application - INFO - Application started
2023-08-31 08:42:11,025 - telegram.ext.Application - INFO - Application started
2023-08-31 08:42:24,293 - telegram.ext.Application - ERROR - No error handlers are registered, logging exception.
Traceback (most recent call last):
  File "/home/runner/Telegram-Bot-Generate-Wallet/.pythonlibs/lib/python3.10/site-packages/telegram/ext/_application.py", line 1173, in process_update
    await coroutine
  File "/home/runner/Telegram-Bot-Generate-Wallet/.pythonlibs/lib/python3.10/site-packages/telegram/ext/_conversationhandler.py", line 825, in handle_update
    new_state: object = await handler.handle_update(
  File "/home/runner/Telegram-Bot-Generate-Wallet/.pythonlibs/lib/python3.10/site-packages/telegram/ext/_basehandler.py", line 141, in handle_update
    return await self.callback(update, context)
  File "main.py", line 79, in show_wallet_menu
    message_text = f"Current deposit address: `{address}`\nCurrent ETH balance: {eth_balance}\nCurrent USDT balance: {usdt_balance}"
NameError: name 'address' is not defined
2023-08-31 08:44:34,451 - telegram.ext.Application - INFO - Application started
2023-08-31 08:44:42,376 - telegram.ext.Application - ERROR - No error handlers are registered, logging exception.
Traceback (most recent call last):
  File "/home/runner/Telegram-Bot-Generate-Wallet/.pythonlibs/lib/python3.10/site-packages/telegram/ext/_application.py", line 1173, in process_update
    await coroutine
  File "/home/runner/Telegram-Bot-Generate-Wallet/.pythonlibs/lib/python3.10/site-packages/telegram/ext/_conversationhandler.py", line 825, in handle_update
    new_state: object = await handler.handle_update(
  File "/home/runner/Telegram-Bot-Generate-Wallet/.pythonlibs/lib/python3.10/site-packages/telegram/ext/_basehandler.py", line 141, in handle_update
    return await self.callback(update, context)
  File "main.py", line 78, in show_wallet_menu
    private_key = bytes.fromhex(private_key_str)
NameError: name 'private_key_str' is not defined
2023-08-31 08:47:42,603 - telegram.ext.Application - INFO - Application started
2023-08-31 08:48:01,306 - telegram.ext.Application - ERROR - No error handlers are registered, logging exception.
Traceback (most recent call last):
  File "/home/runner/Telegram-Bot-Generate-Wallet/.pythonlibs/lib/python3.10/site-packages/telegram/ext/_application.py", line 1173, in process_update
    await coroutine
  File "/home/runner/Telegram-Bot-Generate-Wallet/.pythonlibs/lib/python3.10/site-packages/telegram/ext/_conversationhandler.py", line 825, in handle_update
    new_state: object = await handler.handle_update(
  File "/home/runner/Telegram-Bot-Generate-Wallet/.pythonlibs/lib/python3.10/site-packages/telegram/ext/_basehandler.py", line 141, in handle_update
    return await self.callback(update, context)
TypeError: show_wallet_menu() missing 2 required positional arguments: 'private_key_str' and 'user_id'
2023-08-31 09:10:20,217 - telegram.ext.Application - INFO - Application started
2023-08-31 09:10:46,404 - telegram.ext.Application - INFO - Application started
2023-08-31 09:10:56,609 - telegram.ext.Application - ERROR - No error handlers are registered, logging exception.
Traceback (most recent call last):
  File "/home/runner/Telegram-Bot-Generate-Wallet/.pythonlibs/lib/python3.10/site-packages/telegram/ext/_application.py", line 1173, in process_update
    await coroutine
  File "/home/runner/Telegram-Bot-Generate-Wallet/.pythonlibs/lib/python3.10/site-packages/telegram/ext/_conversationhandler.py", line 825, in handle_update
    new_state: object = await handler.handle_update(
  File "/home/runner/Telegram-Bot-Generate-Wallet/.pythonlibs/lib/python3.10/site-packages/telegram/ext/_basehandler.py", line 141, in handle_update
    return await self.callback(update, context)
  File "main.py", line 90, in show_wallet_menu
    await update.callback_query.message.edit_message_reply_markup(
AttributeError: 'Message' object has no attribute 'edit_message_reply_markup'
2023-08-31 09:14:03,213 - telegram.ext.Application - INFO - Application started
2023-08-31 09:14:37,094 - telegram.ext.Application - ERROR - No error handlers are registered, logging exception.
Traceback (most recent call last):
  File "/home/runner/Telegram-Bot-Generate-Wallet/.pythonlibs/lib/python3.10/site-packages/telegram/ext/_application.py", line 1173, in process_update
    await coroutine
  File "/home/runner/Telegram-Bot-Generate-Wallet/.pythonlibs/lib/python3.10/site-packages/telegram/ext/_conversationhandler.py", line 825, in handle_update
    new_state: object = await handler.handle_update(
  File "/home/runner/Telegram-Bot-Generate-Wallet/.pythonlibs/lib/python3.10/site-packages/telegram/ext/_basehandler.py", line 141, in handle_update
    return await self.callback(update, context)
TypeError: show_wallet_menu() missing 2 required positional arguments: 'private_key_str' and 'user_id'
2023-08-31 09:17:11,823 - telegram.ext.Application - INFO - Application started
2023-08-31 09:18:21,028 - telegram.ext.Application - INFO - Application started
2023-08-31 09:18:35,552 - root - INFO - Entered delete_wallet function
2023-08-31 09:18:35,762 - root - INFO - Attempting to delete file: private_keys/6117012777_private_key.txt
2023-08-31 09:18:35,773 - root - INFO - Successfully deleted private key for user 6117012777
2023-08-31 09:25:35,223 - telegram.ext.Application - INFO - Application started
2023-08-31 09:27:48,703 - telegram.ext.Application - INFO - Application started
2023-08-31 09:47:26,169 - root - INFO - Entered delete_wallet function
2023-08-31 09:47:27,811 - root - INFO - Attempting to delete file: private_keys/6117012777_private_key.txt
2023-08-31 09:47:27,822 - root - INFO - Successfully deleted private key for user 6117012777
2023-08-31 09:54:18,132 - telegram.ext.Application - INFO - Application started
2023-08-31 09:57:02,701 - telegram.ext.Application - INFO - Application started
2023-08-31 10:01:47,531 - telegram.ext.Application - INFO - Application started
2023-08-31 10:05:40,832 - telegram.ext.Application - INFO - Application started
2023-08-31 10:12:05,607 - telegram.ext.Application - INFO - Application started
2023-08-31 10:16:14,013 - telegram.ext.Application - INFO - Application started
2023-08-31 10:20:17,283 - telegram.ext.Application - INFO - Application started
2023-08-31 10:23:05,286 - telegram.ext.Application - INFO - Application started
2023-08-31 10:31:22,002 - telegram.ext.Application - INFO - Application started
2023-08-31 10:33:54,571 - telegram.ext.Application - INFO - Application started
2023-08-31 10:45:44,019 - telegram.ext.Application - INFO - Application started
2023-08-31 10:46:08,404 - telegram.ext.Application - ERROR - No error handlers are registered, logging exception.
Traceback (most recent call last):
  File "/home/runner/Telegram-Bot-Generate-Wallet/.pythonlibs/lib/python3.10/site-packages/telegram/ext/_application.py", line 1173, in process_update
    await coroutine
  File "/home/runner/Telegram-Bot-Generate-Wallet/.pythonlibs/lib/python3.10/site-packages/telegram/ext/_conversationhandler.py", line 825, in handle_update
    new_state: object = await handler.handle_update(
  File "/home/runner/Telegram-Bot-Generate-Wallet/.pythonlibs/lib/python3.10/site-packages/telegram/ext/_basehandler.py", line 141, in handle_update
    return await self.callback(update, context)
  File "main.py", line 44, in start
    return await show_main_menu(update, context)
  File "main.py", line 65, in show_main_menu
    address = generate_wallet(private_key)
  File "/home/runner/Telegram-Bot-Generate-Wallet/wallet.py", line 26, in generate_wallet
    public_key = keys.PrivateKey(private_key).public_key
  File "/home/runner/Telegram-Bot-Generate-Wallet/.pythonlibs/lib/python3.10/site-packages/eth_keys/datatypes.py", line 251, in __init__
    validate_private_key_bytes(private_key_bytes)
  File "/home/runner/Telegram-Bot-Generate-Wallet/.pythonlibs/lib/python3.10/site-packages/eth_keys/validation.py", line 89, in validate_private_key_bytes
    validate_bytes_length(value, 32, "private key")
  File "/home/runner/Telegram-Bot-Generate-Wallet/.pythonlibs/lib/python3.10/site-packages/eth_keys/validation.py", line 54, in validate_bytes_length
    raise ValidationError(
eth_utils.exceptions.ValidationError: Unexpected private key length: Expected 32, but got 0 bytes
2023-08-31 10:46:38,396 - telegram.ext.Application - INFO - Application started
2023-08-31 10:46:56,580 - telegram.ext.Application - ERROR - No error handlers are registered, logging exception.
Traceback (most recent call last):
  File "/home/runner/Telegram-Bot-Generate-Wallet/.pythonlibs/lib/python3.10/site-packages/telegram/ext/_application.py", line 1173, in process_update
    await coroutine
  File "/home/runner/Telegram-Bot-Generate-Wallet/.pythonlibs/lib/python3.10/site-packages/telegram/ext/_conversationhandler.py", line 825, in handle_update
    new_state: object = await handler.handle_update(
  File "/home/runner/Telegram-Bot-Generate-Wallet/.pythonlibs/lib/python3.10/site-packages/telegram/ext/_basehandler.py", line 141, in handle_update
    return await self.callback(update, context)
  File "main.py", line 44, in start
    return await show_main_menu(update, context)
  File "main.py", line 65, in show_main_menu
    address = generate_wallet(private_key)
  File "/home/runner/Telegram-Bot-Generate-Wallet/wallet.py", line 26, in generate_wallet
    public_key = keys.PrivateKey(private_key).public_key
  File "/home/runner/Telegram-Bot-Generate-Wallet/.pythonlibs/lib/python3.10/site-packages/eth_keys/datatypes.py", line 251, in __init__
    validate_private_key_bytes(private_key_bytes)
  File "/home/runner/Telegram-Bot-Generate-Wallet/.pythonlibs/lib/python3.10/site-packages/eth_keys/validation.py", line 89, in validate_private_key_bytes
    validate_bytes_length(value, 32, "private key")
  File "/home/runner/Telegram-Bot-Generate-Wallet/.pythonlibs/lib/python3.10/site-packages/eth_keys/validation.py", line 54, in validate_bytes_length
    raise ValidationError(
eth_utils.exceptions.ValidationError: Unexpected private key length: Expected 32, but got 0 bytes
2023-08-31 10:54:30,302 - telegram.ext.Application - INFO - Application started
2023-08-31 10:54:35,615 - telegram.ext.Application - ERROR - No error handlers are registered, logging exception.
Traceback (most recent call last):
  File "/home/runner/Telegram-Bot-Generate-Wallet/.pythonlibs/lib/python3.10/site-packages/telegram/ext/_application.py", line 1173, in process_update
    await coroutine
  File "/home/runner/Telegram-Bot-Generate-Wallet/.pythonlibs/lib/python3.10/site-packages/telegram/ext/_conversationhandler.py", line 825, in handle_update
    new_state: object = await handler.handle_update(
  File "/home/runner/Telegram-Bot-Generate-Wallet/.pythonlibs/lib/python3.10/site-packages/telegram/ext/_basehandler.py", line 141, in handle_update
    return await self.callback(update, context)
  File "main.py", line 62, in start
    private_key = await read_or_generate_private_key(user_id)
  File "main.py", line 52, in read_or_generate_private_key
    new_private_key = generate_new_private_key()
NameError: name 'generate_new_private_key' is not defined
2023-08-31 11:00:21,505 - telegram.ext.Application - INFO - Application started
2023-08-31 11:03:37,347 - telegram.ext.Application - INFO - Application started
2023-08-31 11:04:42,255 - __main__ - INFO - Transaction successful for user_id: 6117012777, to_address: 0xD5042ba7e365CeA492Ee9a2715c5cf47a012663a
2023-08-31 11:06:57,962 - telegram.ext.Application - INFO - Application started
2023-08-31 11:07:45,070 - __main__ - INFO - Transaction successful for user_id: 6117012777, to_address: 0xD5042ba7e365CeA492Ee9a2715c5cf47a012663a
2023-08-31 11:08:56,916 - telegram.ext.Application - INFO - Application started
2023-08-31 11:09:25,043 - __main__ - INFO - Transaction successful for user_id: 6117012777, to_address: 0xD5042ba7e365CeA492Ee9a2715c5cf47a012663a
2023-08-31 11:09:33,452 - root - INFO - Entered delete_wallet function
2023-08-31 11:09:33,703 - root - INFO - Attempting to delete file: private_keys/6117012777_private_key.txt
2023-08-31 11:09:33,704 - root - INFO - Successfully deleted private key for user 6117012777
2023-08-31 11:11:37,705 - telegram.ext.Application - INFO - Application started
2023-08-31 11:11:55,310 - root - INFO - Entered delete_wallet function
2023-08-31 11:11:55,509 - root - INFO - Attempting to delete file: private_keys/6117012777_private_key.txt
2023-08-31 11:11:55,510 - root - INFO - Successfully deleted private key for user 6117012777
2023-08-31 11:47:40,338 - telegram.ext.Application - INFO - Application started
2023-08-31 11:59:24,596 - telegram.ext.Application - INFO - Application started
2023-08-31 12:01:06,193 - __main__ - INFO - Entered input_eth_address
2023-08-31 12:22:25,741 - telegram.ext.Application - INFO - Application started
2023-08-31 12:25:21,314 - telegram.ext.Application - INFO - Application started
2023-08-31 12:25:54,467 - __main__ - INFO - Entered input_usdt_address
2023-08-31 12:25:55,009 - __main__ - ERROR - An exception occurred: name 'usdt_contract_address' is not defined
2023-08-31 12:26:54,039 - telegram.ext.Application - INFO - Application started
2023-08-31 12:27:38,233 - __main__ - INFO - Entered input_usdt_address
2023-08-31 12:38:38,408 - telegram.ext.Application - INFO - Application started
2023-08-31 12:39:16,307 - __main__ - INFO - Entered input_usdt_address
An error occurred: 
Could not identify the intended function with name `transfer`, positional arguments with type(s) `address,float` and keyword arguments with type(s) `{}`.
Found 1 function(s) with the name `transfer`: ['transfer(address,uint256)']
Function invocation failed due to no matching argument types.. USDT balance was: 1.0
2023-08-31 12:42:37,805 - telegram.ext.Application - INFO - Application started
2023-08-31 12:42:47,801 - __main__ - INFO - Entered input_usdt_address
An error occurred: 'transfer' object has no attribute 'buildTransaction'. USDT balance was: 1000000
2023-08-31 12:44:16,149 - telegram.ext.Application - INFO - Application started
2023-08-31 12:44:37,313 - __main__ - INFO - Entered input_usdt_address
An error occurred: 'transfer' object has no attribute 'buildTransaction'. USDT balance was: 1000000
2023-08-31 12:47:09,474 - telegram.ext.Application - INFO - Application started
2023-08-31 12:47:21,187 - __main__ - INFO - Entered input_usdt_address
2023-08-31 12:47:22,353 - __main__ - INFO - Transaction successful for user_id: 6117012777, to_address: 0xD5042ba7e365CeA492Ee9a2715c5cf47a012663a
2023-08-31 12:48:20,565 - __main__ - INFO - Transaction successful for user_id: 6117012777, to_address: 0xD5042ba7e365CeA492Ee9a2715c5cf47a012663a
2023-08-31 12:48:38,019 - root - INFO - Entered delete_wallet function
2023-08-31 12:48:38,410 - root - INFO - Attempting to delete file: private_keys/6117012777_private_key.txt
2023-08-31 12:48:38,471 - root - INFO - Successfully deleted private key for user 6117012777
